<?xml version="1.0"?>
<robot name="giskard"
  xmlns:xacro="http://ros.org/wiki/xacro">

  <!-- Define robot constants -->
  <xacro:property name="base_width" value="0.31"/>
  <xacro:property name="base_length" value="0.42"/>
  <xacro:property name="base_height" value="0.18"/>

  <xacro:property name="wheel_radius" value="0.10"/>
  <xacro:property name="wheel_width" value="0.04"/>
  <xacro:property name="wheel_ygap" value="0.025"/>
  <xacro:property name="wheel_zoff" value="0.05"/>
  <xacro:property name="wheel_xoff" value="0.12"/>
  

  <!-- Include the inertial file -->
  <xacro:include filename="inertial.xacro" />

  <!-- Robot Base -->
  <link name="base_link">
    <visual>
      <geometry>
        <box size="${base_length} ${base_width} ${base_height}"/>
      </geometry>
      <material name="Cyan">
        <color rgba="0 1.0 1.0 1.0"/>
      </material>
    </visual>

    <collision>
      <geometry>
        <box size="${base_length} ${base_width} ${base_height}"/>
      </geometry>
    </collision>

    <xacro:box_inertia m="15" w="${base_width}" d="${base_length}" h="${base_height}"/>
  </link>

  <!-- Robot Footprint -->
  <link name="base_footprint">
    <xacro:box_inertia m="0" w="0" d="0" h="0"/>
  </link>

  <joint name="base_joint" type="fixed">
    <parent link="base_link"/>
    <child link="base_footprint"/>
    <origin xyz="0.0 0.0 ${-(wheel_radius+wheel_zoff)}" rpy="0 0 0"/>
  </joint>

  <!-- Wheels -->
  <xacro:macro name="wheel" params="prefix x_reflect y_reflect">
    <link name="${prefix}_link">
      <visual>
        <origin xyz="0 0 0" rpy="${pi/2} 0 0"/>
        <geometry>
            <cylinder radius="${wheel_radius}" length="${wheel_width}"/>
        </geometry>
        <material name="Gray">
          <color rgba="0.5 0.5 0.5 1.0"/>
        </material>
      </visual>

      <collision>
        <origin xyz="0 0 0" rpy="${pi/2} 0 0"/>
        <geometry>
          <cylinder radius="${wheel_radius}" length="${wheel_width}"/>
        </geometry>
      </collision>

      <xacro:cylinder_inertia m="0.5" r="${wheel_radius}" h="${wheel_width}"/>
    </link>

    <joint name="${prefix}_joint" type="continuous">
      <parent link="base_link"/>
      <child link="${prefix}_link"/>
      <origin xyz="${x_reflect*wheel_xoff} ${y_reflect*(base_width/2+wheel_ygap)} ${-wheel_zoff}" rpy="0 0 0"/>
      <axis xyz="0 1 0"/>
    </joint>
  </xacro:macro>

  <xacro:wheel prefix="drivewhl_fl" x_reflect="1" y_reflect="1" />
  <xacro:wheel prefix="drivewhl_fr" x_reflect="1" y_reflect="-1" />
  <xacro:wheel prefix="drivewhl_rl" x_reflect="-1" y_reflect="1" />
  <xacro:wheel prefix="drivewhl_rr" x_reflect="-1" y_reflect="-1" />
  
  
  <gazebo>
    <plugin name='wheel_drive_controller' filename='libgazebo_ros_diff_drive.so'>
      <ros>
        <namespace>/demo</namespace>
      </ros>

      <!-- wheels -->
      <num_wheel_pairs>2</num_wheel_pairs>
      <left_joint>drivewhl_fl_joint</left_joint>
      <left_joint>drivewhl_rl_joint</left_joint>
      <right_joint>drivewhl_fr_joint</right_joint>
      <right_joint>drivewhl_rr_joint</right_joint>

      <!-- kinematics -->
      <wheel_separation>0.39</wheel_separation>
      <wheel_diameter>0.2</wheel_diameter>

      <!-- limits -->
      <max_wheel_torque>20</max_wheel_torque>
      <max_wheel_acceleration>1.0</max_wheel_acceleration>

      <!-- output -->
      <publish_odom>true</publish_odom>
      <publish_odom_tf>false</publish_odom_tf>
      <publish_wheel_tf>true</publish_wheel_tf>

      <odometry_frame>odom</odometry_frame>
      <robot_base_frame>base_link</robot_base_frame>
    </plugin>
  </gazebo>

</robot>
